Traceback (most recent call last):
  File "C:\Users\vance\anaconda3\envs\spatial\Lib\site-packages\jupyter_cache\executors\utils.py", line 58, in single_nb_execution
    executenb(
  File "C:\Users\vance\anaconda3\envs\spatial\Lib\site-packages\nbclient\client.py", line 1305, in execute
    return NotebookClient(nb=nb, resources=resources, km=km, **kwargs).execute()
           ^^^^^^^^^^^^^^^^^^^^^^^^^^^^^^^^^^^^^^^^^^^^^^^^^^^^^^^^^^^^^^^^^^^^^
  File "C:\Users\vance\anaconda3\envs\spatial\Lib\site-packages\jupyter_core\utils\__init__.py", line 165, in wrapped
    return loop.run_until_complete(inner)
           ^^^^^^^^^^^^^^^^^^^^^^^^^^^^^^
  File "C:\Users\vance\anaconda3\envs\spatial\Lib\asyncio\base_events.py", line 654, in run_until_complete
    return future.result()
           ^^^^^^^^^^^^^^^
  File "C:\Users\vance\anaconda3\envs\spatial\Lib\site-packages\nbclient\client.py", line 705, in async_execute
    await self.async_execute_cell(
  File "C:\Users\vance\anaconda3\envs\spatial\Lib\site-packages\nbclient\client.py", line 1058, in async_execute_cell
    await self._check_raise_for_error(cell, cell_index, exec_reply)
  File "C:\Users\vance\anaconda3\envs\spatial\Lib\site-packages\nbclient\client.py", line 914, in _check_raise_for_error
    raise CellExecutionError.from_cell_and_msg(cell, exec_reply_content)
nbclient.exceptions.CellExecutionError: An error occurred while executing the following cell:
------------------
var dataset = ee.ImageCollection('NASA/ORNL/biomass_carbon_density/v1');

var visualization = {
  bands: ['agb'],
  min: -50.0,
  max: 80.0,
  palette: ['d9f0a3', 'addd8e', '78c679', '41ab5d', '238443', '005a32']
};

Map.setCenter(-60.0, 7.0, 4);

Map.addLayer(dataset, visualization, 'Aboveground biomass carbon');
------------------


[1;36m  Cell [1;32mIn[1], line 1[1;36m[0m
[1;33m    var dataset = ee.ImageCollection('NASA/ORNL/biomass_carbon_density/v1');[0m
[1;37m        ^[0m
[1;31mSyntaxError[0m[1;31m:[0m invalid syntax


